<?xml version="1.0" ?>

<robot name="mrm" xmlns:xacro="http://www.ros.org/wiki/xacro">
    <link name="base_link">
        <visual>
            <origin rpy="0 0 0" xyz="0 0 0"/>
            <geometry>
                <cylinder radius="1" length="0.2"/>
            </geometry>
        </visual>
    </link>

    <joint name="base_link__link1" type="revolute">
        <axis xyz="0 0 1" />
        <limit effort="1000.0" lower="-1.3" upper="1.3" velocity="0.5" />
        <origin rpy="0 0 0" xyz="0 0 0.1"/>
        <parent link="base_link"/>
        <child link="link1"/>
    </joint>

    <link name="link1">
        <visual>
            <origin rpy="0 0 0" xyz="0 0 0.1"/>
            <geometry>
                <cylinder radius="0.5" length="0.2"/>
            </geometry>
        </visual>
    </link>

    <joint name="link1__link2" type="revolute">
        <axis xyz="1 0 0" />
        <limit effort="1000.0" lower="-1.3" upper="1.3" velocity="0.5" />
        <origin rpy="0 0 0" xyz="0 0 0.3"/>
        <parent link="link1"/>
        <child link="link2"/>
    </joint>

    <link name="link2">
        <visual>
            <origin rpy="0 0 0" xyz="0 0 0.4"/>
            <geometry>
                <cylinder radius="0.2" length="1"/>
            </geometry>
        </visual>
    </link>

    <joint name="link2__link3" type="revolute">
        <axis xyz="1 0 0" />
        <limit effort="1000.0" lower="-1.3" upper="1.3" velocity="0.5" />
        <origin rpy="0 0 0" xyz="0 0 0.9"/>
        <parent link="link2"/>
        <child link="link3"/>
    </joint>

    <link name="link3">
        <visual>
            <origin rpy="0 0 0" xyz="0 0 0.5"/>
            <geometry>
                <cylinder radius="0.2" length="1"/>
            </geometry>
        </visual>
    </link>

    <joint name="link3__link4" type="revolute">
        <axis xyz="1 0 0" />
        <limit effort="1000.0" lower="-1.3" upper="1.3" velocity="0.5" />
        <origin rpy="0 0 0" xyz="0 0 1"/>
        <parent link="link3"/>
        <child link="link4"/>
    </joint>

    <link name="link4">
        <visual>
            <origin rpy="0 0 0" xyz="0 0 0.5"/>
            <geometry>
                <cylinder radius="0.2" length="1"/>
            </geometry>
        </visual>
    </link>

    <joint name="link4__tool" type="fixed">
        <origin rpy="0 0 0" xyz="0 0 1"/>
        <parent link="link4"/>
        <child link="tool"/>
    </joint>

    <link name="tool">
        <visual>
            <origin rpy="0 0 0" xyz="0 0 0.04"/>
            <geometry>
                <box size="1 0.3 0.08" />
            </geometry>
        </visual>
    </link>

</robot>